<robot name = "robot">
    <link name="Link0">
        <inertial>
            <origin xyz="0 0 0.2355154899864827" rpy="0 0 0"/>
            <mass value="1" />
            <inertia ixx="100" ixy="0" ixz="0" iyy="100" iyz="0" izz="100" />
        </inertial>
        <visual>
            <origin xyz="0 0 0.2355154899864827" rpy="0 0 0"/>
            <geometry>
                <box size="0.8268495298164329 0.4710309799729654 0.4710309799729654" />
            </geometry>
            <material name="Green">
                <color rgba="0 1.0 0 1.0"/>
            </material>
        </visual>
        <collision>
            <origin xyz="0 0 0.2355154899864827" rpy="0 0 0"/>
            <geometry>
                <box size="0.8268495298164329 0.4710309799729654 0.4710309799729654" />
            </geometry>
        </collision>
    </link>
    <joint name="Link0_Link1" type="revolute">
       <parent link="Link0"/>
       <child  link="Link1"/>
       <origin rpy="0 0 0" xyz="0.41342476490821645 0 0.2355154899864827" />
       <axis xyz="0.8121281847341797 0.8083701151567984 0.8312786859905937"/>
       <limit effort="0.0" lower="-3.14159" upper="3.14159" velocity="0.0"/>
    </joint>
    <link name="Link1">
        <inertial>
            <origin xyz="0.10452629242453043 0 0" rpy="0 0 0"/>
            <mass value="1" />
            <inertia ixx="100" ixy="0" ixz="0" iyy="100" iyz="0" izz="100" />
        </inertial>
        <visual>
            <origin xyz="0.10452629242453043 0 0" rpy="0 0 0"/>
            <geometry>
                <box size="0.20905258484906086 0.4922610991810721 0.4922610991810721" />
            </geometry>
            <material name="Green">
                <color rgba="0 1.0 0 1.0"/>
            </material>
        </visual>
        <collision>
            <origin xyz="0.10452629242453043 0 0" rpy="0 0 0"/>
            <geometry>
                <box size="0.20905258484906086 0.4922610991810721 0.4922610991810721" />
            </geometry>
        </collision>
    </link>
    <joint name="Link1_Link2" type="revolute">
       <parent link="Link1"/>
       <child  link="Link2"/>
       <origin rpy="0 0 0" xyz="-0.10452629242453043 0 0" />
       <axis xyz="0.7760336969528621 0.21468845490656652 0.9080948769971683"/>
       <limit effort="0.0" lower="-3.14159" upper="3.14159" velocity="0.0"/>
    </joint>
    <link name="Link2">
        <inertial>
            <origin xyz="-0.1459784507949382 0 0" rpy="0 0 0"/>
            <mass value="1" />
            <inertia ixx="100" ixy="0" ixz="0" iyy="100" iyz="0" izz="100" />
        </inertial>
        <visual>
            <origin xyz="-0.1459784507949382 0 0" rpy="0 0 0"/>
            <geometry>
                <box size="0.2919569015898764 0.951055271479538 0.951055271479538" />
            </geometry>
            <material name="Blue">
                <color rgba="0 0 1.0 1.0"/>
            </material>
        </visual>
        <collision>
            <origin xyz="-0.1459784507949382 0 0" rpy="0 0 0"/>
            <geometry>
                <box size="0.2919569015898764 0.951055271479538 0.951055271479538" />
            </geometry>
        </collision>
    </link>
    <joint name="Link2_Link3" type="revolute">
       <parent link="Link2"/>
       <child  link="Link3"/>
       <origin rpy="0 0 0" xyz="0.1459784507949382 0 0" />
       <axis xyz="0.5829138293521593 0.9455934128787277 0.6926426689019555"/>
       <limit effort="0.0" lower="-3.14159" upper="3.14159" velocity="0.0"/>
    </joint>
    <link name="Link3">
        <inertial>
            <origin xyz="0.4037199069403788 0 0" rpy="0 0 0"/>
            <mass value="1" />
            <inertia ixx="100" ixy="0" ixz="0" iyy="100" iyz="0" izz="100" />
        </inertial>
        <visual>
            <origin xyz="0.4037199069403788 0 0" rpy="0 0 0"/>
            <geometry>
                <box size="0.8074398138807576 0.1768955740321151 0.1768955740321151" />
            </geometry>
            <material name="Blue">
                <color rgba="0 0 1.0 1.0"/>
            </material>
        </visual>
        <collision>
            <origin xyz="0.4037199069403788 0 0" rpy="0 0 0"/>
            <geometry>
                <box size="0.8074398138807576 0.1768955740321151 0.1768955740321151" />
            </geometry>
        </collision>
    </link>
</robot>